[
    {
        "user": "U5Q3P94NT",
        "type": "message",
        "ts": "1501042529.518775",
        "text": "Until now my program worked, now I'm getting JSON error during login:\nTraceback (most recent call last):\n  File \"D:\/01_PhD\/Fogadas\/BETFAIR0,5\/main.py\", line 39, in &lt;module&gt;\n    trading.login()\n  File \"C:\\Python27\\lib\\site-packages\\betfairlightweight\\endpoints\\login.py\", line 26, in __call__\n    (response, elapsed_time) = self.request(self.url, session=session)\n  File \"C:\\Python27\\lib\\site-packages\\betfairlightweight\\endpoints\\login.py\", line 41, in request\n    response_data = response.json()\n  File \"C:\\Python27\\lib\\site-packages\\requests\\models.py\", line 894, in json\n    return complexjson.loads(self.text, **kwargs)\n  File \"C:\\Python27\\lib\\json\\__init__.py\", line 339, in loads\n    return _default_decoder.decode(s)\n  File \"C:\\Python27\\lib\\json\\decoder.py\", line 364, in decode\n    obj, end = self.raw_decode(s, idx=_w(s, 0).end())\n  File \"C:\\Python27\\lib\\json\\decoder.py\", line 382, in raw_decode\n    raise ValueError(\"No JSON object could be decoded\")\nValueError: No JSON object could be decoded",
        "team": "T4G9NBD2M",
        "user_team": "T4G9NBD2M",
        "source_team": "T4G9NBD2M",
        "user_profile": {
            "avatar_hash": "g43e9b1c6ad9",
            "image_72": "https:\/\/secure.gravatar.com\/avatar\/a43e9b1c6ad9a5396cd9ab85c42e67be.jpg?s=72&d=https%3A%2F%2Fa.slack-edge.com%2Fdf10d%2Fimg%2Favatars%2Fava_0005-72.png",
            "first_name": "Levente",
            "real_name": "Levente Sz.",
            "display_name": "magiclevinho",
            "team": "T4G9NBD2M",
            "name": "magiclevinho",
            "is_restricted": false,
            "is_ultra_restricted": false
        },
        "blocks": [
            {
                "type": "rich_text",
                "block_id": "AgE",
                "elements": [
                    {
                        "type": "rich_text_section",
                        "elements": [
                            {
                                "type": "text",
                                "text": "Until now my program worked, now I'm getting JSON error during login:\nTraceback (most recent call last):\n  File \"D:\/01_PhD\/Fogadas\/BETFAIR0,5\/main.py\", line 39, in <module>\n    trading.login()\n  File \"C:\\Python27\\lib\\site-packages\\betfairlightweight\\endpoints\\login.py\", line 26, in __call__\n    (response, elapsed_time) = self.request(self.url, session=session)\n  File \"C:\\Python27\\lib\\site-packages\\betfairlightweight\\endpoints\\login.py\", line 41, in request\n    response_data = response.json()\n  File \"C:\\Python27\\lib\\site-packages\\requests\\models.py\", line 894, in json\n    return complexjson.loads(self.text, **kwargs)\n  File \"C:\\Python27\\lib\\json\\__init__.py\", line 339, in loads\n    return _default_decoder.decode(s)\n  File \"C:\\Python27\\lib\\json\\decoder.py\", line 364, in decode\n    obj, end = self.raw_decode(s, idx=_w(s, 0).end())\n  File \"C:\\Python27\\lib\\json\\decoder.py\", line 382, in raw_decode\n    raise ValueError(\"No JSON object could be decoded\")\nValueError: No JSON object could be decoded"
                            }
                        ]
                    }
                ]
            }
        ]
    }
]