[
    {
        "user": "UPMUFSGCR",
        "type": "message",
        "ts": "1599330863.020500",
        "client_msg_id": "2974f086-23e4-492f-a96f-5dc4cd63c65f",
        "text": "Has anyone seen this issue before?\n\nOops no service available at <https:\/\/api.betfair.com\/exchange\/betting\/json-rpc\/v1> HTTP Error 502: Bad Gateway Traceback",
        "team": "T4G9NBD2M",
        "user_team": "T4G9NBD2M",
        "source_team": "T4G9NBD2M",
        "user_profile": {
            "avatar_hash": "31c0bb5a442c",
            "image_72": "https:\/\/avatars.slack-edge.com\/2019-10-28\/812386967189_31c0bb5a442c5b8d2c61_72.png",
            "first_name": "Jon",
            "real_name": "Jon Jon Jon Jon Jon Jon Jon Jon",
            "display_name": "Jonjonjon",
            "team": "T4G9NBD2M",
            "name": "fcmisc",
            "is_restricted": false,
            "is_ultra_restricted": false
        },
        "blocks": [
            {
                "type": "rich_text",
                "block_id": "nt3",
                "elements": [
                    {
                        "type": "rich_text_section",
                        "elements": [
                            {
                                "type": "text",
                                "text": "Has anyone seen this issue before?\n\nOops no service available at "
                            },
                            {
                                "type": "link",
                                "url": "https:\/\/api.betfair.com\/exchange\/betting\/json-rpc\/v1"
                            },
                            {
                                "type": "text",
                                "text": " HTTP Error 502: Bad Gateway Traceback"
                            }
                        ]
                    }
                ]
            }
        ]
    },
    {
        "user": "UPMUFSGCR",
        "type": "message",
        "ts": "1599331382.021700",
        "client_msg_id": "a9f51e4d-5a33-409c-952d-3deea785fade",
        "text": "Ah, please ignore that. I fixed it. I have very bad infrastructure and a legacy bot does not use BFLW. It is on an old server that I don't have time to move. And I accidently killed the proxy server I used this morning. My own fault for being disorganised.",
        "team": "T4G9NBD2M",
        "user_team": "T4G9NBD2M",
        "source_team": "T4G9NBD2M",
        "user_profile": {
            "avatar_hash": "31c0bb5a442c",
            "image_72": "https:\/\/avatars.slack-edge.com\/2019-10-28\/812386967189_31c0bb5a442c5b8d2c61_72.png",
            "first_name": "Jon",
            "real_name": "Jon Jon Jon Jon Jon Jon Jon Jon",
            "display_name": "Jonjonjon",
            "team": "T4G9NBD2M",
            "name": "fcmisc",
            "is_restricted": false,
            "is_ultra_restricted": false
        },
        "blocks": [
            {
                "type": "rich_text",
                "block_id": "yAMZ",
                "elements": [
                    {
                        "type": "rich_text_section",
                        "elements": [
                            {
                                "type": "text",
                                "text": "Ah, please ignore that. I fixed it. I have very bad infrastructure and a legacy bot does not use BFLW. It is on an old server that I don't have time to move. And I accidently killed the proxy server I used this morning. My own fault for being disorganised."
                            }
                        ]
                    }
                ]
            }
        ]
    },
    {
        "user": "U011VL3CA2Y",
        "type": "message",
        "ts": "1599343697.023200",
        "client_msg_id": "1f1b6b5f-4152-4ae1-b211-9e81daa4dbbc",
        "text": "there's something that is keeping me a bit worried....I run my market recorder on a very modest server (1 GB RAM), and yesterday the python process suddenly stopped, without any errors\/warnings in the log, nor in stdout. I have no clue what could have caused this, any ideas?",
        "team": "T4G9NBD2M",
        "user_team": "T4G9NBD2M",
        "source_team": "T4G9NBD2M",
        "user_profile": {
            "avatar_hash": "g1ec6e88d1e4",
            "image_72": "https:\/\/secure.gravatar.com\/avatar\/1ec6e88d1e4dd0bff349d83e9edba6bd.jpg?s=72&d=https%3A%2F%2Fa.slack-edge.com%2Fdf10d%2Fimg%2Favatars%2Fava_0005-72.png",
            "first_name": "Ruben",
            "real_name": "Ruben",
            "display_name": "Ruben",
            "team": "T4G9NBD2M",
            "name": "tduqruqtgtpiioibww",
            "is_restricted": false,
            "is_ultra_restricted": false
        },
        "blocks": [
            {
                "type": "rich_text",
                "block_id": "G9W1",
                "elements": [
                    {
                        "type": "rich_text_section",
                        "elements": [
                            {
                                "type": "text",
                                "text": "there's something that is keeping me a bit worried....I run my market recorder on a very modest server (1 GB RAM), and yesterday the python process suddenly stopped, without any errors\/warnings in the log, nor in stdout. I have no clue what could have caused this, any ideas?"
                            }
                        ]
                    }
                ]
            }
        ]
    },
    {
        "user": "U011VL3CA2Y",
        "type": "message",
        "ts": "1599343717.023600",
        "edited": {
            "user": "U011VL3CA2Y",
            "ts": "1599343727.000000"
        },
        "client_msg_id": "3802647c-a966-41ef-ba17-8f91cfdecb6f",
        "text": "Other processes that were running in the machine continued to run normally",
        "team": "T4G9NBD2M",
        "user_team": "T4G9NBD2M",
        "source_team": "T4G9NBD2M",
        "user_profile": {
            "avatar_hash": "g1ec6e88d1e4",
            "image_72": "https:\/\/secure.gravatar.com\/avatar\/1ec6e88d1e4dd0bff349d83e9edba6bd.jpg?s=72&d=https%3A%2F%2Fa.slack-edge.com%2Fdf10d%2Fimg%2Favatars%2Fava_0005-72.png",
            "first_name": "Ruben",
            "real_name": "Ruben",
            "display_name": "Ruben",
            "team": "T4G9NBD2M",
            "name": "tduqruqtgtpiioibww",
            "is_restricted": false,
            "is_ultra_restricted": false
        },
        "blocks": [
            {
                "type": "rich_text",
                "block_id": "Dphk",
                "elements": [
                    {
                        "type": "rich_text_section",
                        "elements": [
                            {
                                "type": "text",
                                "text": "Other processes that were running in the machine continued to run normally"
                            }
                        ]
                    }
                ]
            }
        ]
    },
    {
        "user": "U0128E7BEHW",
        "type": "message",
        "ts": "1599345048.024000",
        "client_msg_id": "abfd808f-9b52-4df0-96e4-056b5fe6afb1",
        "text": "Was it an OOM kill?",
        "team": "T4G9NBD2M",
        "user_team": "T4G9NBD2M",
        "source_team": "T4G9NBD2M",
        "user_profile": {
            "avatar_hash": "gb57a2bdd15a",
            "image_72": "https:\/\/secure.gravatar.com\/avatar\/b57a2bdd15acccdb845ce257f38940cc.jpg?s=72&d=https%3A%2F%2Fa.slack-edge.com%2Fdf10d%2Fimg%2Favatars%2Fava_0024-72.png",
            "first_name": "Dave",
            "real_name": "Dave R",
            "display_name": "Dave",
            "team": "T4G9NBD2M",
            "name": "d7m",
            "is_restricted": false,
            "is_ultra_restricted": false
        },
        "blocks": [
            {
                "type": "rich_text",
                "block_id": "1kR4",
                "elements": [
                    {
                        "type": "rich_text_section",
                        "elements": [
                            {
                                "type": "text",
                                "text": "Was it an OOM kill?"
                            }
                        ]
                    }
                ]
            }
        ]
    },
    {
        "user": "U0128E7BEHW",
        "type": "message",
        "ts": "1599345090.024400",
        "client_msg_id": "84ba8522-6a4b-4304-93b6-29df491e3a72",
        "text": "Or by stop do you mean it just became hung",
        "team": "T4G9NBD2M",
        "user_team": "T4G9NBD2M",
        "source_team": "T4G9NBD2M",
        "user_profile": {
            "avatar_hash": "gb57a2bdd15a",
            "image_72": "https:\/\/secure.gravatar.com\/avatar\/b57a2bdd15acccdb845ce257f38940cc.jpg?s=72&d=https%3A%2F%2Fa.slack-edge.com%2Fdf10d%2Fimg%2Favatars%2Fava_0024-72.png",
            "first_name": "Dave",
            "real_name": "Dave R",
            "display_name": "Dave",
            "team": "T4G9NBD2M",
            "name": "d7m",
            "is_restricted": false,
            "is_ultra_restricted": false
        },
        "blocks": [
            {
                "type": "rich_text",
                "block_id": "fEBa",
                "elements": [
                    {
                        "type": "rich_text_section",
                        "elements": [
                            {
                                "type": "text",
                                "text": "Or by stop do you mean it just became hung"
                            }
                        ]
                    }
                ]
            }
        ]
    },
    {
        "user": "U016TGY3676",
        "type": "message",
        "ts": "1599349072.030000",
        "client_msg_id": "9f370e2a-a6d4-4070-b721-dc594d309f10",
        "text": "Agree with <@U0128E7BEHW>. Python Memory Error triggers the OOM process killer on Linux systems. Usually happens if you're appending to a list\/dict\/etc but forgetting to remove old entries and\/or limiting the size. For lists, it's simply a case of doing something like `mylist = mylist[-1000:]`",
        "team": "T4G9NBD2M",
        "user_team": "T4G9NBD2M",
        "source_team": "T4G9NBD2M",
        "user_profile": {
            "avatar_hash": "g6a681220e11",
            "image_72": "https:\/\/secure.gravatar.com\/avatar\/6a681220e11c1a2ed3685375d658dadb.jpg?s=72&d=https%3A%2F%2Fa.slack-edge.com%2Fdf10d%2Fimg%2Favatars%2Fava_0001-72.png",
            "first_name": "",
            "real_name": "birchy",
            "display_name": "birchy",
            "team": "T4G9NBD2M",
            "name": "birchy",
            "is_restricted": false,
            "is_ultra_restricted": false
        },
        "blocks": [
            {
                "type": "rich_text",
                "block_id": "6d+Z",
                "elements": [
                    {
                        "type": "rich_text_section",
                        "elements": [
                            {
                                "type": "text",
                                "text": "Agree with "
                            },
                            {
                                "type": "user",
                                "user_id": "U0128E7BEHW"
                            },
                            {
                                "type": "text",
                                "text": ". Python Memory Error triggers the OOM process killer on Linux systems. Usually happens if you're appending to a list\/dict\/etc but forgetting to remove old entries and\/or limiting the size. For lists, it's simply a case of doing something like "
                            },
                            {
                                "type": "text",
                                "text": "mylist = mylist[-1000:]",
                                "style": {
                                    "code": true
                                }
                            }
                        ]
                    }
                ]
            }
        ]
    }
]