[
    {
        "subtype": "channel_join",
        "user": "U02PGKJB5QD",
        "text": "<@U02PGKJB5QD> has joined the channel",
        "type": "message",
        "ts": "1638734051.238300"
    },
    {
        "subtype": "channel_join",
        "user": "U02PKRD1QV9",
        "text": "<@U02PKRD1QV9> has joined the channel",
        "type": "message",
        "ts": "1638748853.238500"
    },
    {
        "user": "U016TGY3676",
        "type": "message",
        "ts": "1638776741.242500",
        "client_msg_id": "67b6dbdf-4e5e-468b-af20-23ef2c7e16cb",
        "text": "Bit of a weird problem this morning. Went to restart my marketrecorder that's been running for months and am getting this on startup:\n`Traceback (most recent call last):\n  File \"data_recorder.py\", line 118, in &lt;module&gt;\n    framework.run()\n  File \"\/home\/ubuntu\/.local\/lib\/python3.6\/site-packages\/flumine\/flumine.py\", line 29, in run\n    self._process_raw_data(event)\n  File \"\/home\/ubuntu\/.local\/lib\/python3.6\/site-packages\/flumine\/baseflumine.py\", line 203, in _process_raw_data\n    strategy.process_raw_data(clk, publish_time, datum)TypeError: process_raw_data() takes 3 positional arguments but 4 were given`\nNot on my pc, so unable to debug ATM.\nFlumine: 1.20.13\nBflw: 2.15.2",
        "team": "T4G9NBD2M",
        "user_team": "T4G9NBD2M",
        "source_team": "T4G9NBD2M",
        "user_profile": {
            "avatar_hash": "g6a681220e11",
            "image_72": "https:\/\/secure.gravatar.com\/avatar\/6a681220e11c1a2ed3685375d658dadb.jpg?s=72&d=https%3A%2F%2Fa.slack-edge.com%2Fdf10d%2Fimg%2Favatars%2Fava_0001-72.png",
            "first_name": "",
            "real_name": "birchy",
            "display_name": "birchy",
            "team": "T4G9NBD2M",
            "name": "birchy",
            "is_restricted": false,
            "is_ultra_restricted": false
        },
        "blocks": [
            {
                "type": "rich_text",
                "block_id": "pPM",
                "elements": [
                    {
                        "type": "rich_text_section",
                        "elements": [
                            {
                                "type": "text",
                                "text": "Bit of a weird problem this morning. Went to restart my marketrecorder that's been running for months and am getting this on startup:\n"
                            },
                            {
                                "type": "text",
                                "text": "Traceback (most recent call last):\n  File \"data_recorder.py\", line 118, in <module>\n    framework.run()\n  File \"\/home\/ubuntu\/.local\/lib\/python3.6\/site-packages\/flumine\/flumine.py\", line 29, in run\n    self._process_raw_data(event)\n  File \"\/home\/ubuntu\/.local\/lib\/python3.6\/site-packages\/flumine\/baseflumine.py\", line 203, in _process_raw_data\n    strategy.process_raw_data(clk, publish_time, datum)TypeError: process_raw_data() takes 3 positional arguments but 4 were given",
                                "style": {
                                    "code": true
                                }
                            },
                            {
                                "type": "text",
                                "text": "\nNot on my pc, so unable to debug ATM.\nFlumine: 1.20.13\nBflw: 2.15.2"
                            }
                        ]
                    }
                ]
            }
        ]
    },
    {
        "user": "UBS7QANF3",
        "type": "message",
        "ts": "1638777298.243000",
        "client_msg_id": "dbc26c3e-e561-494a-a91d-5207593e7fe9",
        "text": "The signature for `process_raw_data` changed in 1.20.10",
        "team": "T4G9NBD2M",
        "user_team": "T4G9NBD2M",
        "source_team": "T4G9NBD2M",
        "user_profile": {
            "avatar_hash": "gaaf844a4a90",
            "image_72": "https:\/\/secure.gravatar.com\/avatar\/eaaf844a4a905431d83430e563b077aa.jpg?s=72&d=https%3A%2F%2Fa.slack-edge.com%2Fdf10d%2Fimg%2Favatars%2Fava_0011-72.png",
            "first_name": "",
            "real_name": "Maurice Berk",
            "display_name": "Mo",
            "team": "T4G9NBD2M",
            "name": "maurice",
            "is_restricted": false,
            "is_ultra_restricted": false
        },
        "blocks": [
            {
                "type": "rich_text",
                "block_id": "F=Zm2",
                "elements": [
                    {
                        "type": "rich_text_section",
                        "elements": [
                            {
                                "type": "text",
                                "text": "The signature for "
                            },
                            {
                                "type": "text",
                                "text": "process_raw_data",
                                "style": {
                                    "code": true
                                }
                            },
                            {
                                "type": "text",
                                "text": " changed in "
                            },
                            {
                                "type": "text",
                                "text": "1.20.10",
                                "style": {
                                    "unlink": true
                                }
                            }
                        ]
                    }
                ]
            }
        ]
    }
]