[
    {
        "user": "UBS7QANF3",
        "type": "message",
        "ts": "1681970221.099299",
        "client_msg_id": "f6c66834-88cd-49c6-81b3-fed78591c379",
        "text": "Sorry, keep meaning to reply to this:\n\n1. The GitHub repo for CPython is here: <https:\/\/github.com\/python\/cpython>\n2. The tag for version 3.9.16 is here: <https:\/\/github.com\/python\/cpython\/tree\/v3.9.16>\n3. The _ssl.c file referenced in your exception is here: <https:\/\/github.com\/python\/cpython\/blob\/v3.9.16\/Modules\/_ssl.c>\n4. The line referenced in your exception is here: <https:\/\/github.com\/python\/cpython\/blob\/595f9ccb0c059f2fb5bf13643bfc0cdd5b55a422\/Modules\/_ssl.c#L4044>\n5. All I can personally infer at this stage is that a) the problem is with your certificate b) the problem is NOT related to the certificate file's password c) the problem is NOT some OS error such as being unable to find the certificate file",
        "team": "T4G9NBD2M",
        "user_team": "T4G9NBD2M",
        "source_team": "T4G9NBD2M",
        "user_profile": {
            "avatar_hash": "gaaf844a4a90",
            "image_72": "https:\/\/secure.gravatar.com\/avatar\/eaaf844a4a905431d83430e563b077aa.jpg?s=72&d=https%3A%2F%2Fa.slack-edge.com%2Fdf10d%2Fimg%2Favatars%2Fava_0011-72.png",
            "first_name": "",
            "real_name": "Maurice Berk",
            "display_name": "Mo",
            "team": "T4G9NBD2M",
            "name": "maurice",
            "is_restricted": false,
            "is_ultra_restricted": false
        },
        "thread_ts": "1681665134.137979",
        "parent_user_id": "U053U2PUK2M",
        "blocks": [
            {
                "type": "rich_text",
                "block_id": "wM7o6",
                "elements": [
                    {
                        "type": "rich_text_section",
                        "elements": [
                            {
                                "type": "text",
                                "text": "Sorry, keep meaning to reply to this:\n\n"
                            }
                        ]
                    },
                    {
                        "type": "rich_text_list",
                        "elements": [
                            {
                                "type": "rich_text_section",
                                "elements": [
                                    {
                                        "type": "text",
                                        "text": "The GitHub repo for CPython is here: "
                                    },
                                    {
                                        "type": "link",
                                        "url": "https:\/\/github.com\/python\/cpython"
                                    }
                                ]
                            },
                            {
                                "type": "rich_text_section",
                                "elements": [
                                    {
                                        "type": "text",
                                        "text": "The tag for version 3.9.16 is here: "
                                    },
                                    {
                                        "type": "link",
                                        "url": "https:\/\/github.com\/python\/cpython\/tree\/v3.9.16"
                                    }
                                ]
                            },
                            {
                                "type": "rich_text_section",
                                "elements": [
                                    {
                                        "type": "text",
                                        "text": "The _ssl.c file referenced in your exception is here: "
                                    },
                                    {
                                        "type": "link",
                                        "url": "https:\/\/github.com\/python\/cpython\/blob\/v3.9.16\/Modules\/_ssl.c"
                                    }
                                ]
                            },
                            {
                                "type": "rich_text_section",
                                "elements": [
                                    {
                                        "type": "text",
                                        "text": "The line referenced in your exception is here: "
                                    },
                                    {
                                        "type": "link",
                                        "url": "https:\/\/github.com\/python\/cpython\/blob\/595f9ccb0c059f2fb5bf13643bfc0cdd5b55a422\/Modules\/_ssl.c#L4044"
                                    }
                                ]
                            },
                            {
                                "type": "rich_text_section",
                                "elements": [
                                    {
                                        "type": "text",
                                        "text": "All I can personally infer at this stage is that a) the problem is with your certificate b) the problem is NOT related to the certificate file's password c) the problem is NOT some OS error such as being unable to find the certificate file"
                                    }
                                ]
                            }
                        ],
                        "style": "ordered",
                        "indent": 0,
                        "border": 0
                    }
                ]
            }
        ]
    },
    {
        "user": "UBS7QANF3",
        "type": "message",
        "ts": "1681970445.366169",
        "client_msg_id": "9235d9f7-0d81-40c1-8d36-5d6f7399899d",
        "text": "Speculating rampantly, it could be some discrepancy between the cipher used to encrypt the certificate and the ciphers available in whatever version of OpenSSL you're running on GCP",
        "team": "T4G9NBD2M",
        "user_team": "T4G9NBD2M",
        "source_team": "T4G9NBD2M",
        "user_profile": {
            "avatar_hash": "gaaf844a4a90",
            "image_72": "https:\/\/secure.gravatar.com\/avatar\/eaaf844a4a905431d83430e563b077aa.jpg?s=72&d=https%3A%2F%2Fa.slack-edge.com%2Fdf10d%2Fimg%2Favatars%2Fava_0011-72.png",
            "first_name": "",
            "real_name": "Maurice Berk",
            "display_name": "Mo",
            "team": "T4G9NBD2M",
            "name": "maurice",
            "is_restricted": false,
            "is_ultra_restricted": false
        },
        "thread_ts": "1681665134.137979",
        "parent_user_id": "U053U2PUK2M",
        "blocks": [
            {
                "type": "rich_text",
                "block_id": "dMuZ",
                "elements": [
                    {
                        "type": "rich_text_section",
                        "elements": [
                            {
                                "type": "text",
                                "text": "Speculating rampantly, it could be some discrepancy between the cipher used to encrypt the certificate and the ciphers available in whatever version of OpenSSL you're running on GCP"
                            }
                        ]
                    }
                ]
            }
        ]
    }
]